# Should throw exception

def main(x):
    return foo(x)

def foo(x):
    y = x + 1